<?xml version="1.0"?>
<robot name="roomba" xmlns:xacro="http://www.ros.org/wiki/xacro">
  <material name="purple">
    <color rgba="1.0 0.0 1.0 2.5"/>
  </material>  
  <material name="grey">
    <color rgba="0.5 0.5 0.5 2.5"/>
  </material>
  <material name="blue">
    <color rgba="0.0 0.0 1.0 2.5"/>
  </material>
  
  <xacro:macro name="wheel_macro" params="parent prefix xyz">
    <joint name="${prefix}_joint" type="continuous">
      <origin xyz="${xyz}" rpy="${radians(-90)} 0 0"/>
      <parent link="${parent}"/>
      <child  link="${prefix}_link"/>
      <axis xyz="0 0 1" />
      <limit velocity="12.0" effort="0.4" />
      <dynamics damping="0.1"/>
    </joint>
    <transmission name="${prefix}_trans">
      <type>transmission_interface/SimpleTransmission</type>
      <joint name="${prefix}_joint">
          <hardwareInterface>hardware_interface/VelocityJointInterface</hardwareInterface>
      </joint>
      <actuator name="${prefix}_motor">
        <hardwareInterface>hardware_interface/VelocityJointInterface</hardwareInterface>
        <mechanismReduction>1</mechanismReduction>
      </actuator>
    </transmission>
    <link name="${prefix}_link">
      <inertial>
        <origin xyz="0 0 0" rpy="0 0 0"/>
        <mass value="0.1"/>
        <inertia ixx="0.0001" ixy="0.0" ixz="0.0" iyy="0.0001" iyz="0.0" izz="0.0001"/>
      </inertial>
      <visual>
        <geometry>
          <cylinder radius="0.03" length="0.01" />
        </geometry>
        <material name="grey"/>
      </visual>
      <collision>
        <geometry>
          <cylinder radius="0.03" length="0.01" />
        </geometry>
      </collision>
    </link>
    <gazebo reference="${prefix}_link">
      <material>Gazebo/Grey</material>
      <mu1 value="2.5" />
      <mu2 value="2.5" />
      <kp value="50000" />
      <kd value="10" />
    </gazebo>
  </xacro:macro> 

  <xacro:wheel_macro prefix="left_wheel"  parent="base_link" xyz="0 0.1 0.03"/>
  <xacro:wheel_macro prefix="right_wheel" parent="base_link" xyz="0 -0.1 0.03"/>

  <link name="base_link"/>

  <joint name="body_joint" type="fixed">
    <parent link="base_link"/>
    <child  link="body_link"/>
    <origin xyz="-0.05 0 0.02" rpy="0 0 0"/>
  </joint>
  <link name="body_link">
    <inertial>
      <origin xyz="0 0 0" rpy="0 0 0"/>
      <mass value="0.1"/>
      <inertia ixx="0.0001" ixy="0.0" ixz="0.0" iyy="0.0001" iyz="0.0" izz="0.0001"/>
    </inertial>
    <visual>
      <geometry>
        <mesh filename="package://rtw_gazebo/stl/Roomba_model.stl" />
      </geometry>
      <origin xyz="0 0 0" rpy="0 0 0"/>
      <material name="purple"/>
    </visual>
  </link>
  <gazebo reference="body_link">
    <material>Gazebo/Purple</material>
  </gazebo>

  <joint name="ball_joint" type="fixed">
    <parent link="base_link"/>
    <child  link="ball_link"/>
    <origin xyz="-0.14 0 0.02" rpy="0 0 0"/>
  </joint>
  <link name="ball_link">
    <visual>
      <origin xyz="0 0 0" rpy="0 0 0" />
      <geometry>
        <sphere radius="0.02" />
      </geometry>
      <material name="grey" />
    </visual>
    <collision>
      <origin xyz="0 0 0" rpy="0 0 0" />
      <geometry>
        <sphere radius="0.02" />
      </geometry>
      <material name="grey" />
    </collision>
  </link>
  <gazebo reference="ball_link">
    <material>Gazebo/Grey</material>
    <mu1 value="0.5" />
    <mu2 value="0.5" />
  </gazebo>
</robot>